Workbook

Sheet 구별_분석표
A1: 연도 | B1: 행정구 | C1: 전통시장수 (23-24 기준) | D1: 골목상권수 (23-24 기준) | E1: 발달상권수 (23-24 기준) | F1: 폐업 | G1: 신규 | H1: 가동증감률 | I1: 폐업/신규
A2: 2025 | B2: 사상구 | C2: 19 | D2: 0 | E2: 7 | F2: 3533 | G2: 3330 | H2: =IFERROR(SUMIFS(가동사업자_원본!$C$2:$C$49,가동사업자_원본!$A$2:$A$49,A2,가동사업자_원본!$B$2:$B$49,B2)/SUMIFS(가동사업자_원본!$C$2:$C$49,가동사업자_원본!$A$2:$A$49,A2-1,가동사업자_원본!$B$2:$B$49,B2)-1,"") -> -0.0090120086 | I2: =IFERROR(F2/G2,"") -> 1.060961
A3: 2025 | B3: 중구 | C3: 18 | D3: 0 | E3: 5 | F3: 1746 | G3: 1684 | H3: =IFERROR(SUMIFS(가동사업자_원본!$C$2:$C$49,가동사업자_원본!$A$2:$A$49,A3,가동사업자_원본!$B$2:$B$49,B3)/SUMIFS(가동사업자_원본!$C$2:$C$49,가동사업자_원본!$A$2:$A$49,A3-1,가동사업자_원본!$B$2:$B$49,B3)-1,"") -> -0.0084811454 | I3: =IFERROR(F3/G3,"") -> 1.0368171
A4: 2025 | B4: 영도구 | C4: 3 | D4: 0 | E4: 4 | F4: 1374 | G4: 1328 | H4: =IFERROR(SUMIFS(가동사업자_원본!$C$2:$C$49,가동사업자_원본!$A$2:$A$49,A4,가동사업자_원본!$B$2:$B$49,B4)/SUMIFS(가동사업자_원본!$C$2:$C$49,가동사업자_원본!$A$2:$A$49,A4-1,가동사업자_원본!$B$2:$B$49,B4)-1,"") -> -0.0049912316 | I4: =IFERROR(F4/G4,"") -> 1.0346386 | K4: 강서구 | L4: 명지국제신도시, 명지오션시티
A5: 2025 | B5: 서구 | C5: 8 | D5: 0 | E5: 1 | F5: 1456 | G5: 1421 | H5: =IFERROR(SUMIFS(가동사업자_원본!$C$2:$C$49,가동사업자_원본!$A$2:$A$49,A5,가동사업자_원본!$B$2:$B$49,B5)/SUMIFS(가동사업자_원본!$C$2:$C$49,가동사업자_원본!$A$2:$A$49,A5-1,가동사업자_원본!$B$2:$B$49,B5)-1,"") -> -0.0058678402 | I5: =IFERROR(F5/G5,"") -> 1.0246305 | K5: 금정구 | L5: 부산대앞, 장전동
A6: 2025 | B6: 금정구 | C6: 8 | D6: 2 | E6: 3 | F6: 3365 | G6: 3348 | H6: =IFERROR(SUMIFS(가동사업자_원본!$C$2:$C$49,가동사업자_원본!$A$2:$A$49,A6,가동사업자_원본!$B$2:$B$49,B6)/SUMIFS(가동사업자_원본!$C$2:$C$49,가동사업자_원본!$A$2:$A$49,A6-1,가동사업자_원본!$B$2:$B$49,B6)-1,"") -> -0.0042237475 | I6: =IFERROR(F6/G6,"") -> 1.0050777 | K6: 기장군 | L6: 오시리아, 기장시장
A7: 2025 | B7: 연제구 | C7: 10 | D7: 0 | E7: 9 | F7: 3648 | G7: 3736 | H7: =IFERROR(SUMIFS(가동사업자_원본!$C$2:$C$49,가동사업자_원본!$A$2:$A$49,A7,가동사업자_원본!$B$2:$B$49,B7)/SUMIFS(가동사업자_원본!$C$2:$C$49,가동사업자_원본!$A$2:$A$49,A7-1,가동사업자_원본!$B$2:$B$49,B7)-1,"") -> 0.0049023899 | I7: =IFERROR(F7/G7,"") -> 0.9764454 | K7: 남구 | L7: 경성대·부경대, 대연동
A8: 2025 | B8: 사하구 | C8: 0 | D8: 1 | E8: 13 | F8: 3797 | G8: 3890 | H8: =IFERROR(SUMIFS(가동사업자_원본!$C$2:$C$49,가동사업자_원본!$A$2:$A$49,A8,가동사업자_원본!$B$2:$B$49,B8)/SUMIFS(가동사업자_원본!$C$2:$C$49,가동사업자_원본!$A$2:$A$49,A8-1,가동사업자_원본!$B$2:$B$49,B8)-1,"") -> -0.00098211517 | I8: =IFERROR(F8/G8,"") -> 0.97609254 | K8: 동구 | L8: 부산역·초량, 부산진시장
A9: 2025 | B9: 북구 | C9: 5 | D9: 0 | E9: 6 | F9: 3275 | G9: 3442 | H9: =IFERROR(SUMIFS(가동사업자_원본!$C$2:$C$49,가동사업자_원본!$A$2:$A$49,A9,가동사업자_원본!$B$2:$B$49,B9)/SUMIFS(가동사업자_원본!$C$2:$C$49,가동사업자_원본!$A$2:$A$49,A9-1,가동사업자_원본!$B$2:$B$49,B9)-1,"") -> -0.00057142857 | I9: =IFERROR(F9/G9,"") -> 0.9514817 | K9: 동래구 | L9: 동래역·명륜동, 온천장
A10: 2025 | B10: 동래구 | C10: 15 | D10: 4 | E10: 8 | F10: 4090 | G10: 4389 | H10: =IFERROR(SUMIFS(가동사업자_원본!$C$2:$C$49,가동사업자_원본!$A$2:$A$49,A10,가동사업자_원본!$B$2:$B$49,B10)/SUMIFS(가동사업자_원본!$C$2:$C$49,가동사업자_원본!$A$2:$A$49,A10-1,가동사업자_원본!$B$2:$B$49,B10)-1,"") -> 0.006164641 | I10: =IFERROR(F10/G10,"") -> 0.93187514 | K10: 부산진구 | L10: 서면, 전포카페거리·전리단길
A11: 2025 | B11: 기장군 | C11: 1 | D11: 3 | E11: 2 | F11: 3200 | G11: 3495 | H11: =IFERROR(SUMIFS(가동사업자_원본!$C$2:$C$49,가동사업자_원본!$A$2:$A$49,A11,가동사업자_원본!$B$2:$B$49,B11)/SUMIFS(가동사업자_원본!$C$2:$C$49,가동사업자_원본!$A$2:$A$49,A11-1,가동사업자_원본!$B$2:$B$49,B11)-1,"") -> 0.014919996 | I11: =IFERROR(F11/G11,"") -> 0.91559371 | K11: 북구 | L11: 덕천동, 구포시장
A12: 2025 | B12: 해운대구 | C12: 0 | D12: 16 | E12: 8 | F12: 6938 | G12: 7593 | H12: =IFERROR(SUMIFS(가동사업자_원본!$C$2:$C$49,가동사업자_원본!$A$2:$A$49,A12,가동사업자_원본!$B$2:$B$49,B12)/SUMIFS(가동사업자_원본!$C$2:$C$49,가동사업자_원본!$A$2:$A$49,A12-1,가동사업자_원본!$B$2:$B$49,B12)-1,"") -> 0.004677581 | I12: =IFERROR(F12/G12,"") -> 0.91373634 | K12: 사상구 | L12: 사상역·서부버스터미널
A13: 2025 | B13: 부산진구 | C13: 31 | D13: 2 | E13: 10 | F13: 6911 | G13: 7598 | H13: =IFERROR(SUMIFS(가동사업자_원본!$C$2:$C$49,가동사업자_원본!$A$2:$A$49,A13,가동사업자_원본!$B$2:$B$49,B13)/SUMIFS(가동사업자_원본!$C$2:$C$49,가동사업자_원본!$A$2:$A$49,A13-1,가동사업자_원본!$B$2:$B$49,B13)-1,"") -> 0.0032934677 | I13: =IFERROR(F13/G13,"") -> 0.90958147 | K13: 사하구 | L13: 하단오거리·동아대
A14: 2025 | B14: 남구 | C14: 0 | D14: 3 | E14: 6 | F14: 3676 | G14: 4053 | H14: =IFERROR(SUMIFS(가동사업자_원본!$C$2:$C$49,가동사업자_원본!$A$2:$A$49,A14,가동사업자_원본!$B$2:$B$49,B14)/SUMIFS(가동사업자_원본!$C$2:$C$49,가동사업자_원본!$A$2:$A$49,A14-1,가동사업자_원본!$B$2:$B$49,B14)-1,"") -> 0.01210106 | I14: =IFERROR(F14/G14,"") -> 0.90698248 | K14: 서구 | L14: 송도
A15: 2025 | B15: 동구 | C15: 12 | D15: 0 | E15: 6 | F15: 2277 | G15: 2547 | H15: =IFERROR(SUMIFS(가동사업자_원본!$C$2:$C$49,가동사업자_원본!$A$2:$A$49,A15,가동사업자_원본!$B$2:$B$49,B15)/SUMIFS(가동사업자_원본!$C$2:$C$49,가동사업자_원본!$A$2:$A$49,A15-1,가동사업자_원본!$B$2:$B$49,B15)-1,"") -> 0.0084683358 | I15: =IFERROR(F15/G15,"") -> 0.89399293 | K15: 수영구 | L15: 광안리, 민락
... A19: 2024 | B19: 사상구 | C19: 19 | D19: 0 | E19: 7 | F19: 3730 | G19: 3602 | H19: =IFERROR(SUMIFS(가동사업자_원본!$C$2:$C$49,가동사업자_원본!$A$2:$A$49,A19,가동사업자_원본!$B$2:$B$49,B19)/SUMIFS(가동사업자_원본!$C$2:$C$49,가동사업자_원본!$A$2:$A$49,A19-1,가동사업자_원본!$B$2:$B$49,B19)-1,"") -> -0.0052112085 | I19: =IFERROR(F19/G19,"") -> 1.0355358 | K19: 해운대구 | L19: 해운대 구남로·해운대시장, 해리단길, 센텀시티, 송정
A20: 2024 | B20: 서구 | C20: 8 | D20: 0 | E20: 1 | F20: 1451 | G20: 1430 | H20: =IFERROR(SUMIFS(가동사업자_원본!$C$2:$C$49,가동사업자_원본!$A$2:$A$49,A20,가동사업자_원본!$B$2:$B$49,B20)/SUMIFS(가동사업자_원본!$C$2:$C$49,가동사업자_원본!$A$2:$A$49,A20-1,가동사업자_원본!$B$2:$B$49,B20)-1,"") -> -0.0060312831 | I20: =IFERROR(F20/G20,"") -> 1.0146853
A21: 2024 | B21: 영도구 | C21: 3 | D21: 0 | E21: 4 | F21: 1459 | G21: 1449 | H21: =IFERROR(SUMIFS(가동사업자_원본!$C$2:$C$49,가동사업자_원본!$A$2:$A$49,A21,가동사업자_원본!$B$2:$B$49,B21)/SUMIFS(가동사업자_원본!$C$2:$C$49,가동사업자_원본!$A$2:$A$49,A21-1,가동사업자_원본!$B$2:$B$49,B21)-1,"") -> -0.003829873 | I21: =IFERROR(F21/G21,"") -> 1.0069013
A22: 2024 | B22: 금정구 | C22: 8 | D22: 2 | E22: 3 | F22: 3503 | G22: 3547 | H22: =IFERROR(SUMIFS(가동사업자_원본!$C$2:$C$49,가동사업자_원본!$A$2:$A$49,A22,가동사업자_원본!$B$2:$B$49,B22)/SUMIFS(가동사업자_원본!$C$2:$C$49,가동사업자_원본!$A$2:$A$49,A22-1,가동사업자_원본!$B$2:$B$49,B22)-1,"") -> -0.0039854972 | I22: =IFERROR(F22/G22,"") -> 0.98759515
A23: 2024 | B23: 사하구 | C23: 0 | D23: 1 | E23: 13 | F23: 4046 | G23: 4290 | H23: =IFERROR(SUMIFS(가동사업자_원본!$C$2:$C$49,가동사업자_원본!$A$2:$A$49,A23,가동사업자_원본!$B$2:$B$49,B23)/SUMIFS(가동사업자_원본!$C$2:$C$49,가동사업자_원본!$A$2:$A$49,A23-1,가동사업자_원본!$B$2:$B$49,B23)-1,"") -> 0.009391631 | I23: =IFERROR(F23/G23,"") -> 0.94312354
A24: 2024 | B24: 동구 | C24: 12 | D24: 0 | E24: 6 | F24: 2126 | G24: 2270 | H24: =IFERROR(SUMIFS(가동사업자_원본!$C$2:$C$49,가동사업자_원본!$A$2:$A$49,A24,가동사업자_원본!$B$2:$B$49,B24)/SUMIFS(가동사업자_원본!$C$2:$C$49,가동사업자_원본!$A$2:$A$49,A24-1,가동사업자_원본!$B$2:$B$49,B24)-1,"") -> 0.001146789 | I24: =IFERROR(F24/G24,"") -> 0.93656388
A25: 2024 | B25: 북구 | C25: 5 | D25: 0 | E25: 6 | F25: 3403 | G25: 3644 | H25: =IFERROR(SUMIFS(가동사업자_원본!$C$2:$C$49,가동사업자_원본!$A$2:$A$49,A25,가동사업자_원본!$B$2:$B$49,B25)/SUMIFS(가동사업자_원본!$C$2:$C$49,가동사업자_원본!$A$2:$A$49,A25-1,가동사업자_원본!$B$2:$B$49,B25)-1,"") -> 0.0033050047 | I25: =IFERROR(F25/G25,"") -> 0.93386389
A26: 2024 | B26: 부산진구 | C26: 31 | D26: 2 | E26: 10 | F26: 7315 | G26: 7991 | H26: =IFERROR(SUMIFS(가동사업자_원본!$C$2:$C$49,가동사업자_원본!$A$2:$A$49,A26,가동사업자_원본!$B$2:$B$49,B26)/SUMIFS(가동사업자_원본!$C$2:$C$49,가동사업자_원본!$A$2:$A$49,A26-1,가동사업자_원본!$B$2:$B$49,B26)-1,"") -> 0.0098551613 | I26: =IFERROR(F26/G26,"") -> 0.91540483
A27: 2024 | B27: 남구 | C27: 0 | D27: 3 | E27: 6 | F27: 3956 | G27: 4334 | H27: =IFERROR(SUMIFS(가동사업자_원본!$C$2:$C$49,가동사업자_원본!$A$2:$A$49,A27,가동사업자_원본!$B$2:$B$49,B27)/SUMIFS(가동사업자_원본!$C$2:$C$49,가동사업자_원본!$A$2:$A$49,A27-1,가동사업자_원본!$B$2:$B$49,B27)-1,"") -> 0.0075239586 | I27: =IFERROR(F27/G27,"") -> 0.91278265
A28: 2024 | B28: 동래구 | C28: 15 | D28: 4 | E28: 8 | F28: 4149 | G28: 4561 | H28: =IFERROR(SUMIFS(가동사업자_원본!$C$2:$C$49,가동사업자_원본!$A$2:$A$49,A28,가동사업자_원본!$B$2:$B$49,B28)/SUMIFS(가동사업자_원본!$C$2:$C$49,가동사업자_원본!$A$2:$A$49,A28-1,가동사업자_원본!$B$2:$B$49,B28)-1,"") -> 0.013048666 | I28: =IFERROR(F28/G28,"") -> 0.90966893
A29: 2024 | B29: 기장군 | C29: 1 | D29: 3 | E29: 2 | F29: 3421 | G29: 3783 | H29: =IFERROR(SUMIFS(가동사업자_원본!$C$2:$C$49,가동사업자_원본!$A$2:$A$49,A29,가동사업자_원본!$B$2:$B$49,B29)/SUMIFS(가동사업자_원본!$C$2:$C$49,가동사업자_원본!$A$2:$A$49,A29-1,가동사업자_원본!$B$2:$B$49,B29)-1,"") -> 0.010741269 | I29: =IFERROR(F29/G29,"") -> 0.90430875
A30: 2024 | B30: 해운대구 | C30: 0 | D30: 16 | E30: 8 | F30: 7301 | G30: 8187 | H30: =IFERROR(SUMIFS(가동사업자_원본!$C$2:$C$49,가동사업자_원본!$A$2:$A$49,A30,가동사업자_원본!$B$2:$B$49,B30)/SUMIFS(가동사업자_원본!$C$2:$C$49,가동사업자_원본!$A$2:$A$49,A30-1,가동사업자_원본!$B$2:$B$49,B30)-1,"") -> 0.010053855 | I30: =IFERROR(F30/G30,"") -> 0.89177965
A31: 2024 | B31: 강서구 | C31: 4 | D31: 5 | E31: 0 | F31: 4123 | G31: 4811 | H31: =IFERROR(SUMIFS(가동사업자_원본!$C$2:$C$49,가동사업자_원본!$A$2:$A$49,A31,가동사업자_원본!$B$2:$B$49,B31)/SUMIFS(가동사업자_원본!$C$2:$C$49,가동사업자_원본!$A$2:$A$49,A31-1,가동사업자_원본!$B$2:$B$49,B31)-1,"") -> 0.013665612 | I31: =IFERROR(F31/G31,"") -> 0.85699439
... A33: 2024 | B33: 연제구 | C33: 10 | D33: 0 | E33: 9 | F33: 3609 | G33: 4276 | H33: =IFERROR(SUMIFS(가동사업자_원본!$C$2:$C$49,가동사업자_원본!$A$2:$A$49,A33,가동사업자_원본!$B$2:$B$49,B33)/SUMIFS(가동사업자_원본!$C$2:$C$49,가동사업자_원본!$A$2:$A$49,A33-1,가동사업자_원본!$B$2:$B$49,B33)-1,"") -> 0.0194556 | I33: =IFERROR(F33/G33,"") -> 0.8440131
A34: 2023 | B34: 중구 | C34: 18 | D34: 0 | E34: 5 | F34: 1892 | G34: 1913 | I34: =IFERROR(F34/G34,"") -> 0.98902248
A35: 2023 | B35: 사상구 | C35: 19 | D35: 0 | E35: 7 | F35: 3927 | G35: 4063 | I35: =IFERROR(F35/G35,"") -> 0.9665272
A36: 2023 | B36: 금정구 | C36: 8 | D36: 2 | E36: 3 | F36: 3645 | G36: 3788 | I36: =IFERROR(F36/G36,"") -> 0.96224921
A37: 2023 | B37: 동구 | C37: 12 | D37: 0 | E37: 6 | F37: 2212 | G37: 2396 | I37: =IFERROR(F37/G37,"") -> 0.92320534
A38: 2023 | B38: 북구 | C38: 5 | D38: 0 | E38: 6 | F38: 3486 | G38: 3838 | I38: =IFERROR(F38/G38,"") -> 0.90828557
A39: 2023 | B39: 서구 | C39: 8 | D39: 0 | E39: 1 | F39: 1434 | G39: 1601 | I39: =IFERROR(F39/G39,"") -> 0.89569019
A40: 2023 | B40: 해운대구 | C40: 0 | D40: 16 | E40: 8 | F40: 8005 | G40: 8948 | I40: =IFERROR(F40/G40,"") -> 0.89461332
A41: 2023 | B41: 영도구 | C41: 3 | D41: 0 | E41: 4 | F41: 1360 | G41: 1529 | I41: =IFERROR(F41/G41,"") -> 0.88947024
A42: 2023 | B42: 동래구 | C42: 15 | D42: 4 | E42: 8 | F42: 4195 | G42: 4841 | I42: =IFERROR(F42/G42,"") -> 0.8665565
A43: 2023 | B43: 남구 | C43: 0 | D43: 3 | E43: 6 | F43: 4104 | G43: 4741 | I43: =IFERROR(F43/G43,"") -> 0.86564016
A44: 2023 | B44: 연제구 | C44: 10 | D44: 0 | E44: 9 | F44: 3616 | G44: 4332 | I44: =IFERROR(F44/G44,"") -> 0.83471837
...

Sheet 가동사업자_원본
A1: 연도 | B1: 행정구 | C1: 가동사업자수
A2: 2023 | B2: 강서구 | C2: 47711
A3: 2024 | B3: 강서구 | C3: 48363
A4: 2025 | B4: 강서구 | C4: 49439
A5: 2023 | B5: 금정구 | C5: 36131
A6: 2024 | B6: 금정구 | C6: 35987
A7: 2025 | B7: 금정구 | C7: 35835
A8: 2023 | B8: 기장군 | C8: 32957
A9: 2024 | B9: 기장군 | C9: 33311
A10: 2025 | B10: 기장군 | C10: 33808
A11: 2023 | B11: 남구 | C11: 36417
A12: 2024 | B12: 남구 | C12: 36691
A13: 2025 | B13: 남구 | C13: 37135
... A49: 2025 | B49: 해운대구 | C49: 72168

Sheet 산출기준
A1: 항목 | B1: 산출/해석 기준
A2: 정렬 | B2: 연도는 최신순(2025→2024→2023), 각 연도 안에서는 폐업/신규율 높은 순으로 정렬
A3: 폐업/신규율 | B3: 폐업수 ÷ 신규수. 100% 초과면 신규보다 폐업이 더 많음
A4: 가동증감률 | B4: (해당연도 가동사업자수 ÷ 전년도 가동사업자수) - 1
A5: 2023 가동증감률 | B5: 제공된 가동사업자 파일이 2023~2025라 2022 값이 없어 계산 불가 → 공란
A6: 상권수 기준 | B6: 이전 제공된 「23-24 부산 상권영역」 285개 기준. 전통시장 154, 골목상권 37, 발달상권 94
A7: 상권 행정구 배정 | B7: 상권 파일에 행정구 컬럼이 없어 상권 geometry와 사업체 위치를 이용해 행정구를 공간적으로 배정하고, 상권명에 행정구가 명시된 경우 그 값을 우선 적용
A8: 주의 | B8: 상권수는 23-24 기준 고정값이므로 2025년의 신규 상권 생성·폐지는 반영하지 않음
